Workbook

Sheet อ่านก่อน
B1: รายการตรวจเนื้อหาแอป 형범 (Hanguk Hyeong-Bum)
B2: แอปเรียนภาษาเกาหลีสำหรับคนไทย — ไฟล์นี้รวมข้อความเกาหลี คำอ่านไทย และคำแปลทั้งแอป เพื่อให้เจ้าของภาษา/ครูช่วยตรวจก่อนเผยแพร่กว้างขึ้น
B4: ใครตรวจอะไร
B5: ผู้ตรวจที่เป็นคนเกาหลี (또는 한국어 선생님) | C5: ตรวจช่อง ①: ภาษาเกาหลีถูกต้อง/เป็นธรรมชาติ/ระดับความสุภาพเหมาะกับผู้พูดหรือไม่ · 한국어 칸 ①만 확인해 주세요 (아래 한국어 안내 참고)
B6: ผู้ตรวจที่อ่านไทยออก (คนไทยที่รู้เกาหลี หรือครูสอนเกาหลี) | C6: ตรวจช่อง ② คำอ่านไทยว่าตรงกับ "เสียงที่ได้ยินจริง" และช่อง ③ คำแปลไทยว่าตรงความหมายและเป็นภาษาไทยที่เป็นธรรมชาติ
B7: ถ้าตรวจคนเดียวทั้งสามช่อง | C7: ได้เลย — แต่ถ้าไม่แน่ใจข้อไหน เลือก "? ไม่แน่ใจ" แล้วเขียนเหตุผล ดีกว่าเดาให้
B9: วิธีกรอก
B10: ช่องสีเหลือง | C10: คือช่องที่ต้องกรอก ช่องสีเทา/ขาวเป็นข้อมูลของแอป ห้ามแก้ (แก้ในช่อง "ข้อเสนอ" แทน)
B11: ตัวเลือกใน ① ② ③ | C11: ✔ ถูกต้อง · ✎ ควรแก้ (ใส่ข้อเสนอในช่องถัดไป) · ? ไม่แน่ใจ — เว้นว่างได้ถ้ายังไม่ได้ตรวจแถวนั้น
B12: ลำดับความสำคัญ | C12: ตรวจแถวที่ "สูง" ก่อน (บทเรียนและเรื่องราว ผู้เรียนเห็นบ่อยที่สุด) แล้วค่อย "กลาง" และ "ต่ำ" (ชื่อไอเทมในร้านค้า) — ใช้ตัวกรองที่หัวคอลัมน์ได้
B13: แถวที่มีหมายเหตุ | C13: ผู้พัฒนาเขียนเตือนไว้ เช่น ประโยคที่ลงท้ายไม่สุภาพ (ตั้งใจให้เป็นคำพูดกันเอง?) หรือคำที่เสียงเปลี่ยนจากตัวเขียน
B15: กฎการถอดเสียงอ่านเกาหลีเป็นไทยที่แอปใช้ (ช่อง ②)
B16: พยัญชนะต้น (เสียงเบา) | C16: ㄱ=ก · ㄷ=ด · ㅂ=บ · ㅈ=จ
B17: พยัญชนะต้น (พ่นลม) | C17: ㅋ=ค · ㅌ=ท · ㅍ=พ · ㅊ=ช
B18: พยัญชนะต้น (เสียงตึง) | C18: ㄲ=ก · ㄸ=ต · ㅃ=ป · ㅉ=จ (ภาษาไทยแยกตึง/เบาไม่ได้ จึงให้เสียงเป็นตัวสนับสนุน)
B19: สระ | C19: ㅐ=แ · ㅔ=เ · ㅚ=เว · ㅙ=แว · ㅓ=ออ · ㅗ=โอ · ㅡ=อือ · สระนำ (เ แ โ ไ) เขียนหน้าพยัญชนะเสมอ
B20: เขียนตามเสียงจริง | C20: เช่น 많아요 → มานาโย · 먹었어요 → มอกอซซอโย (ไม่ใช่ตามตัวเขียน) — ช่อง "เสียงอ่านจริง" ที่สร้างอัตโนมัติไว้ช่วยเทียบ (ผ่านกฎการออกเสียงหลัก อาจผิดในบางคำ)
B21: สิ่งที่ภาษาไทยทำไม่ได้ | C21: ไม่มีเสียงสั้น-ยาวของสระ ไม่มี ㅡ/ㅓ ที่ตรงเป๊ะ และเสียงวรรณยุกต์ไม่ตรงกับน้ำเสียงเกาหลี — คำอ่านไทยเป็นแค่ตัวช่วยเริ่มต้น ผู้เรียนมีเสียงพากย์ฟังคู่กัน
B23: ขอบเขต / สิ่งที่ไม่ต้องตรวจ
B24: ไม่ต้องตรวจ | C24: ภาพ เกม ราคา ระบบรางวัล · ชื่อไอเทมที่เป็นชื่อเฉพาะทำนองสมมติ (ตรวจแค่ว่าเกาหลีใช้พูดกันจริงไหม)
B25: ภาษาเกาหลีมาตรฐานที่ใช้ | C25: เกาหลีใต้ (서울말) สุภาพแบบ -아요/어요 เป็นหลัก ใช้ -ㅂ니다 ในประโยคทางการ (ทักทาย/ขอบคุณ)
B26: ผู้พูดในเรื่อง | C26: คุณยาย (할머니) พูดกับเด็กอย่างอบอุ่น · แม่ค้า · ผู้เล่น (นักเรียนต่างชาติ) · ผู้เล่าเรื่อง · สัตว์เลี้ยง (ใช้ภาษาเด็ก/น่ารักได้) — ดูช่อง "ผู้พูด"
B28: 한국어 안내 (Korean reviewers)
B29: 이 파일은 무엇인가요? | C29: 태국인을 위한 한국어 학습 앱의 모든 한국어 문장과 단어입니다. 원어민의 시각에서 어색하거나 틀린 표현이 없는지 확인해 주세요.
B30: 확인해 주실 부분 | C30: 노란색 칸 ① 「한국어 자연스러움」만 확인해 주시면 됩니다. 태국어(번역·발음 표기) 칸은 건너뛰셔도 됩니다.
B31: 표시 방법 | C31: ✔ 올바름 / ✎ 수정 필요 (옆 칸에 고친 문장을 써 주세요) / ? 잘 모르겠음
B32: 참고 | C32: 화자(할머니·가게 주인·학습자·내레이터·반려동물)에 맞는 말투인지, 띄어쓰기·철자·존댓말 수준이 일관적인지, 실제로 그렇게 말하는지 봐 주세요. 초급 학습자를 위한 문장이라 아주 단순하게 쓴 점은 양해 부탁드립니다.
B34: ตัวอย่างการกรอก (แถวตัวอย่าง ไม่ใช่ข้อมูลจริง)
B35: ช่อง ① = ✎ ควรแก้ | C35: ข้อเสนอ 한국어: 안녕히 가세요 (ผู้พูดเป็นคนที่ "อยู่" จึงใช้ 가세요 กับคนที่กำลังไป)
B36: ช่อง ③ = ? ไม่แน่ใจ | C36: ความเห็นอื่น ๆ: คำแปล "ลาก่อน" ฟังทางการเกินไปสำหรับบทสนทนาของเด็ก

Sheet สรุปความคืบหน้า
A1: ชุดข้อความ | B1: จำนวนแถว | C1: ตรวจ ① แล้ว | D1: ตรวจ ② แล้ว | E1: ตรวจ ③ แล้ว | F1: ทำเครื่องหมาย "ควรแก้" (รวม ①②③)
A2: บทเรียน | B2: =COUNTA('บทเรียน'!E2:E181) | C2: =COUNTA('บทเรียน'!J2:J181) | D2: =COUNTA('บทเรียน'!L2:L181) | E2: =COUNTA('บทเรียน'!N2:N181) | F2: =COUNTIF('บทเรียน'!J2:J181,"✎*")+COUNTIF('บทเรียน'!L2:L181,"✎*")+COUNTIF('บทเรียน'!N2:N181,"✎*")
A3: เรื่องราว | B3: =COUNTA('เรื่องราว'!E2:E283) | C3: =COUNTA('เรื่องราว'!J2:J283) | D3: =COUNTA('เรื่องราว'!L2:L283) | E3: =COUNTA('เรื่องราว'!N2:N283) | F3: =COUNTIF('เรื่องราว'!J2:J283,"✎*")+COUNTIF('เรื่องราว'!L2:L283,"✎*")+COUNTIF('เรื่องราว'!N2:N283,"✎*")
A4: กิจวัตร | B4: =COUNTA('กิจวัตร'!E2:E13) | C4: =COUNTA('กิจวัตร'!J2:J13) | D4: =COUNTA('กิจวัตร'!L2:L13) | E4: =COUNTA('กิจวัตร'!N2:N13) | F4: =COUNTIF('กิจวัตร'!J2:J13,"✎*")+COUNTIF('กิจวัตร'!L2:L13,"✎*")+COUNTIF('กิจวัตร'!N2:N13,"✎*")
A5: สัตว์เลี้ยง | B5: =COUNTA('สัตว์เลี้ยง'!E2:E35) | C5: =COUNTA('สัตว์เลี้ยง'!J2:J35) | D5: =COUNTA('สัตว์เลี้ยง'!L2:L35) | E5: =COUNTA('สัตว์เลี้ยง'!N2:N35) | F5: =COUNTIF('สัตว์เลี้ยง'!J2:J35,"✎*")+COUNTIF('สัตว์เลี้ยง'!L2:L35,"✎*")+COUNTIF('สัตว์เลี้ยง'!N2:N35,"✎*")
A6: ภารกิจ-ความสำเร็จ | B6: =COUNTA('ภารกิจ-ความสำเร็จ'!E2:E47) | C6: =COUNTA('ภารกิจ-ความสำเร็จ'!J2:J47) | D6: =COUNTA('ภารกิจ-ความสำเร็จ'!L2:L47) | E6: =COUNTA('ภารกิจ-ความสำเร็จ'!N2:N47) | F6: =COUNTIF('ภารกิจ-ความสำเร็จ'!J2:J47,"✎*")+COUNTIF('ภารกิจ-ความสำเร็จ'!L2:L47,"✎*")+COUNTIF('ภารกิจ-ความสำเร็จ'!N2:N47,"✎*")
A7: ร้านค้า | B7: =COUNTA('ร้านค้า'!E2:E203) | C7: =COUNTA('ร้านค้า'!J2:J203) | D7: =COUNTA('ร้านค้า'!L2:L203) | E7: =COUNTA('ร้านค้า'!N2:N203) | F7: =COUNTIF('ร้านค้า'!J2:J203,"✎*")+COUNTIF('ร้านค้า'!L2:L203,"✎*")+COUNTIF('ร้านค้า'!N2:N203,"✎*")
A8: รวม | B8: =SUM(B2:B7) | C8: =SUM(C2:C7) | D8: =SUM(D2:D7) | E8: =SUM(E2:E7) | F8: =SUM(F2:F7)
A10: ตัวเลขนี้คำนวณอัตโนมัติจากช่องที่กรอกในแต่ละแท็บ

Sheet บทเรียน
A1: # | B1: ความสำคัญ | C1: ที่มา (หน้า/บท/ฉาก) | D1: ผู้พูด | E1: 한국어 (เกาหลี) | F1: เสียงอ่านจริง (สร้างอัตโนมัติ — กฎการออกเสียง) | G1: คำอ่านไทย (ที่แอปแสดง) | H1: คำแปลไทย (ที่แอปแสดง) | I1: หมายเหตุจากผู้พัฒนา | J1: ① 한국어 ถูกต้อง/เป็นธรรมชาติ? | K1: ① ข้อเสนอแก้ 한국어 | L1: ② คำอ่านไทยตรงกับเสียงจริง? | M1: ② ข้อเสนอคำอ่านไทย | N1: ③ คำแปลไทยถูกต้อง? | O1: ③ ข้อเสนอคำแปล | P1: ความเห็นอื่น ๆ
A2: 1 | B2: สูง | C2: 모음 (สระพื้นฐาน 10 ตัว) · ตัวอักษร | E2: ㅏ | G2: อา | H2: สระ อา | I2: คำตัวอย่าง: 아기 (อากี) = ทารก
A3: 2 | B3: สูง | C3: 모음 (สระพื้นฐาน 10 ตัว) · ตัวอักษร | E3: ㅑ | G3: ยา | H3: สระ ยา | I3: คำตัวอย่าง: 야구 (ยากู) = เบสบอล
A4: 3 | B4: สูง | C4: 모음 (สระพื้นฐาน 10 ตัว) · ตัวอักษร | E4: ㅓ | G4: ออ | H4: สระ ออ | I4: คำตัวอย่าง: 어머니 (ออมอนี) = แม่
A5: 4 | B5: สูง | C5: 모음 (สระพื้นฐาน 10 ตัว) · ตัวอักษร | E5: ㅕ | G5: ยอ | H5: สระ ยอ | I5: คำตัวอย่าง: 여자 (ยอจา) = ผู้หญิง
A6: 5 | B6: สูง | C6: 모음 (สระพื้นฐาน 10 ตัว) · ตัวอักษร | E6: ㅗ | G6: โอ | H6: สระ โอ | I6: คำตัวอย่าง: 오리 (โอรี) = เป็ด
A7: 6 | B7: สูง | C7: 모음 (สระพื้นฐาน 10 ตัว) · ตัวอักษร | E7: ㅛ | G7: โย | H7: สระ โย | I7: คำตัวอย่าง: 요리 (โยรี) = การทำอาหาร
A8: 7 | B8: สูง | C8: 모음 (สระพื้นฐาน 10 ตัว) · ตัวอักษร | E8: ㅜ | G8: อู | H8: สระ อู | I8: คำตัวอย่าง: 우유 (อูยู) = นม
A9: 8 | B9: สูง | C9: 모음 (สระพื้นฐาน 10 ตัว) · ตัวอักษร | E9: ㅠ | G9: ยู | H9: สระ ยู | I9: คำตัวอย่าง: 유리 (ยูรี) = กระจก
A10: 9 | B10: สูง | C10: 모음 (สระพื้นฐาน 10 ตัว) · ตัวอักษร | E10: ㅡ | G10: อือ | H10: สระ อือ | I10: คำตัวอย่าง: 은행 (อึนเฮง) = ธนาคาร
A11: 10 | B11: สูง | C11: 모음 (สระพื้นฐาน 10 ตัว) · ตัวอักษร | E11: ㅣ | G11: อี | H11: สระ อี | I11: คำตัวอย่าง: 이름 (อีรึม) = ชื่อ
A12: 11 | B12: สูง | C12: 모음 · หมายเหตุประจำบท (ข้อความภาษาไทย) | H12: สระเกาหลีเขียนคู่กับ ㅇ (ไม่ออกเสียง) เมื่อขึ้นต้นคำ เช่น ㅏ → 아
A13: 12 | B13: สูง | C13: 자음 1 (พยัญชนะ ชุดที่ 1) · ตัวอักษร | E13: ㄱ | G13: ก | H13: พยัญชนะ ㄱ (기역) | I13: คำตัวอย่าง: 가방 (กาบัง) = กระเป๋า
A14: 13 | B14: สูง | C14: 자음 1 (พยัญชนะ ชุดที่ 1) · ตัวอักษร | E14: ㄴ | G14: น | H14: พยัญชนะ ㄴ (니은) | I14: คำตัวอย่าง: 나무 (นามู) = ต้นไม้
A15: 14 | B15: สูง | C15: 자음 1 (พยัญชนะ ชุดที่ 1) · ตัวอักษร | E15: ㄷ | G15: ด | H15: พยัญชนะ ㄷ (디귿) | I15: คำตัวอย่าง: 다리 (ดารี) = ขา / สะพาน
A16: 15 | B16: สูง | C16: 자음 1 (พยัญชนะ ชุดที่ 1) · ตัวอักษร | E16: ㄹ | G16: ร / ล | H16: พยัญชนะ ㄹ (리을) | I16: คำตัวอย่าง: 라면 (ราเมียน) = ราเมน
A17: 16 | B17: สูง | C17: 자음 1 (พยัญชนะ ชุดที่ 1) · ตัวอักษร | E17: ㅁ | G17: ม | H17: พยัญชนะ ㅁ (미음) | I17: คำตัวอย่าง: 모자 (โมจา) = หมวก
A18: 17 | B18: สูง | C18: 자음 1 (พยัญชนะ ชุดที่ 1) · ตัวอักษร | E18: ㅂ | G18: บ | H18: พยัญชนะ ㅂ (비읍) | I18: คำตัวอย่าง: 바나나 (บานานา) = กล้วย
A19: 18 | B19: สูง | C19: 자음 1 (พยัญชนะ ชุดที่ 1) · ตัวอักษร | E19: ㅅ | G19: ซ | H19: พยัญชนะ ㅅ (시옷) | I19: คำตัวอย่าง: 사과 (ซากวา) = แอปเปิล
A20: 19 | B20: สูง | C20: 자음 1 · หมายเหตุประจำบท (ข้อความภาษาไทย) | H20: ลองอ่านคู่กับสระ ㅏ: 가 나 다 라 마 바 사 · ㄱ ㄷ ㅂ ㅈ ออกเสียงเบา ไม่พ่นลม (แทนด้วย ก ด บ จ) ส่วน ㅋ ㅌ ㅍ ㅊ ที่จะเรียนต่อไปพ่นลมแรง (ค ท พ ช)
A21: 20 | B21: สูง | C21: 자음 2 (พยัญชนะ ชุดที่ 2) · ตัวอักษร | E21: ㅇ | G21: อ / ง | H21: พยัญชนะ ㅇ (이응) | I21: คำตัวอย่าง: 아이 (อาอี) = เด็ก
A22: 21 | B22: สูง | C22: 자음 2 (พยัญชนะ ชุดที่ 2) · ตัวอักษร | E22: ㅈ | G22: จ | H22: พยัญชนะ ㅈ (지읒) | I22: คำตัวอย่าง: 자동차 (จาดงชา) = รถยนต์
A23: 22 | B23: สูง | C23: 자음 2 (พยัญชนะ ชุดที่ 2) · ตัวอักษร | E23: ㅊ | G23: ช (พ่นลม) | H23: พยัญชนะ ㅊ (치읓) | I23: คำตัวอย่าง: 치마 (ชีมา) = กระโปรง
A24: 23 | B24: สูง | C24: 자음 2 (พยัญชนะ ชุดที่ 2) · ตัวอักษร | E24: ㅋ | G24: ค (พ่นลม) | H24: พยัญชนะ ㅋ (키읔) | I24: คำตัวอย่าง: 커피 (คอพี) = กาแฟ
A25: 24 | B25: สูง | C25: 자음 2 (พยัญชนะ ชุดที่ 2) · ตัวอักษร | E25: ㅌ | G25: ท (พ่นลม) | H25: พยัญชนะ ㅌ (티읕) | I25: คำตัวอย่าง: 토마토 (โทมาโท) = มะเขือเทศ
A26: 25 | B26: สูง | C26: 자음 2 (พยัญชนะ ชุดที่ 2) · ตัวอักษร | E26: ㅍ | G26: พ (พ่นลม) | H26: พยัญชนะ ㅍ (피읖) | I26: คำตัวอย่าง: 포도 (โพโด) = องุ่น
A27: 26 | B27: สูง | C27: 자음 2 (พยัญชนะ ชุดที่ 2) · ตัวอักษร | E27: ㅎ | G27: ฮ | H27: พยัญชนะ ㅎ (히읗) | I27: คำตัวอย่าง: 하늘 (ฮานึล) = ท้องฟ้า
A28: 27 | B28: สูง | C28: 자음 2 · หมายเหตุประจำบท (ข้อความภาษาไทย) | H28: ㅇ ต้นคำไม่ออกเสียง แต่ตัวสะกดออกเสียง ง เช่น 강 (คัง)
A29: 28 | B29: สูง | C29: 받침 1 (ตัวสะกด 7 เสียง) · คำศัพท์ | E29: 박 | G29: บัก | H29: ตัวสะกด ㄱ ㅋ ㄲ → เสียง k (แม่กก)
A30: 29 | B30: สูง | C30: 받침 1 (ตัวสะกด 7 เสียง) · คำศัพท์ | E30: 안 | G30: อัน | H30: ตัวสะกด ㄴ → เสียง n (แม่กน)
A31: 30 | B31: สูง | C31: 받침 1 (ตัวสะกด 7 เสียง) · คำศัพท์ | E31: 옷 | F31: 옫 | G31: โอด | H31: ตัวสะกด ㅅ ㅈ ㅊ ㅌ ㅎ ㄷ → เสียง t (แม่กด)
A32: 31 | B32: สูง | C32: 받침 1 (ตัวสะกด 7 เสียง) · คำศัพท์ | E32: 물 | G32: มุล | H32: ตัวสะกด ㄹ → เสียง l (ลิ้นแตะเพดานปาก)
A33: 32 | B33: สูง | C33: 받침 1 (ตัวสะกด 7 เสียง) · คำศัพท์ | E33: 밤 | G33: บัม | H33: ตัวสะกด ㅁ → เสียง m (แม่กม)
A34: 33 | B34: สูง | C34: 받침 1 (ตัวสะกด 7 เสียง) · คำศัพท์ | E34: 밥 | G34: บับ | H34: ตัวสะกด ㅂ ㅍ → เสียง p (แม่กบ)
A35: 34 | B35: สูง | C35: 받침 1 (ตัวสะกด 7 เสียง) · คำศัพท์ | E35: 강 | G35: กัง | H35: ตัวสะกด ㅇ → เสียง ng (แม่กง)
A36: 35 | B36: สูง | C36: 받침 1 · หมายเหตุประจำบท (ข้อความภาษาไทย) | H36: พยัญชนะใต้พยางค์ (받침) ออกเสียงได้แค่ 7 แบบ — คล้ายแม่กก กด กบ กน กม กง ของไทย ฟังแล้วท่องเป็นชุดได้เลย
A37: 36 | B37: สูง | C37: 받침 단어 (คำที่มีตัวสะกด) · คำศัพท์ | E37: 집 | G37: จิบ | H37: บ้าน
A38: 37 | B38: สูง | C38: 받침 단어 (คำที่มีตัวสะกด) · คำศัพท์ | E38: 책 | G38: แชก | H38: หนังสือ
A39: 38 | B39: สูง | C39: 받침 단어 (คำที่มีตัวสะกด) · คำศัพท์ | E39: 꽃 | F39: 꼳 | G39: โกด | H39: ดอกไม้
A40: 39 | B40: สูง | C40: 받침 단어 (คำที่มีตัวสะกด) · คำศัพท์ | E40: 달 | G40: ดัล | H40: ดวงจันทร์ / เดือน
...

Sheet เรื่องราว
A1: # | B1: ความสำคัญ | C1: ที่มา (หน้า/บท/ฉาก) | D1: ผู้พูด | E1: 한국어 (เกาหลี) | F1: เสียงอ่านจริง (สร้างอัตโนมัติ — กฎการออกเสียง) | G1: คำอ่านไทย (ที่แอปแสดง) | H1: คำแปลไทย (ที่แอปแสดง) | I1: หมายเหตุจากผู้พัฒนา | J1: ① 한국어 ถูกต้อง/เป็นธรรมชาติ? | K1: ① ข้อเสนอแก้ 한국어 | L1: ② คำอ่านไทยตรงกับเสียงจริง? | M1: ② ข้อเสนอคำอ่านไทย | N1: ③ คำแปลไทยถูกต้อง? | O1: ③ ข้อเสนอคำแปล | P1: ความเห็นอื่น ๆ
A2: 1 | B2: สูง | C2: เรื่อง · 오래된 가게 (ร้านเก่าแก่) · ฉาก 1 | D2: ผู้เล่าเรื่อง | E2: 서울의 작은 골목. 오래된 가게예요. | F2: 서우릐 자근 골목. 오래된 가게예요. | G2: ซออูเร จากึน โกลมก โอแรเดวน กาเกเยโย | H2: ซอยเล็กๆ กลางโซล มีร้านเก่าแก่ร้านหนึ่ง
A3: 2 | B3: สูง | C3: เรื่อง · 오래된 가게 (ร้านเก่าแก่) · ฉาก 1 · คำศัพท์ | E3: 가게 | H3: ร้านค้า
A4: 3 | B4: สูง | C4: เรื่อง · 오래된 가게 (ร้านเก่าแก่) · ฉาก 2 | D4: คุณยาย | E4: 어서 오세요. | G4: ออซอ โอเซโย | H4: ยินดีต้อนรับจ้ะ
A5: 4 | B5: สูง | C5: เรื่อง · 오래된 가게 (ร้านเก่าแก่) · ฉาก 2 · คำศัพท์ | E5: 어서 오세요 | H5: ยินดีต้อนรับ
A6: 5 | B6: สูง | C6: เรื่อง · 오래된 가게 (ร้านเก่าแก่) · ฉาก 3 | D6: ผู้เล่น | E6: 안녕하세요! 이거 얼마예요? | F6: 안녕하세요! 이거 얼마예요? | G6: อันนยองฮาเซโย อีกอ ออลมาเยโย | H6: สวัสดี! อันนี้ราคาเท่าไหร่ครับ/คะ
A7: 6 | B7: สูง | C7: เรื่อง · 오래된 가게 (ร้านเก่าแก่) · ฉาก 3 · คำศัพท์ | E7: 안녕하세요 | H7: สวัสดี
A8: 7 | B8: สูง | C8: เรื่อง · 오래된 가게 (ร้านเก่าแก่) · ฉาก 3 · คำศัพท์ | E8: 이거 | H8: อันนี้
A9: 8 | B9: สูง | C9: เรื่อง · 오래된 가게 (ร้านเก่าแก่) · ฉาก 3 · คำศัพท์ | E9: 얼마예요? | F9: 얼마예요? | H9: ราคาเท่าไหร่
A10: 9 | B10: สูง | C10: เรื่อง · 오래된 가게 (ร้านเก่าแก่) · ฉาก 4 | D10: คุณยาย | E10: 오천 원이에요. 한국어 공책이에요. | F10: 오천 워니에요. 한구거 공채기에요. | G10: โอชอน วอนอีเอโย ฮันกุกอ กงแชกีเอโย | H10: ห้าพันวอนจ้ะ เป็นสมุดสำหรับจดภาษาเกาหลี
A11: 10 | B11: สูง | C11: เรื่อง · 오래된 가게 (ร้านเก่าแก่) · ฉาก 4 · คำศัพท์ | E11: 오천 원 | H11: 5,000 วอน
A12: 11 | B12: สูง | C12: เรื่อง · 오래된 가게 (ร้านเก่าแก่) · ฉาก 4 · คำศัพท์ | E12: 공책 | H12: สมุด
A13: 12 | B13: สูง | C13: เรื่อง · 오래된 가게 (ร้านเก่าแก่) · ฉาก 5 | D13: ผู้เล่น | E13: 한국어를 배우고 싶어요. | F13: 한구거를 배우고 시퍼요. | G13: ฮันกุกอรึล แบอู โกชิพพอโย | H13: อยากเรียนภาษาเกาหลีค่ะ/ครับ
A14: 13 | B14: สูง | C14: เรื่อง · 오래된 가게 (ร้านเก่าแก่) · ฉาก 5 · คำศัพท์ | E14: 배우다 | H14: เรียน
A15: 14 | B15: สูง | C15: เรื่อง · 오래된 가게 (ร้านเก่าแก่) · ฉาก 5 · คำศัพท์ | E15: 싶어요 | F15: 시퍼요 | H15: อยาก
A16: 15 | B16: สูง | C16: เรื่อง · 오래된 가게 (ร้านเก่าแก่) · ฉาก 6 | D16: คุณยาย | E16: 어머, 한국어를 배워요? 대단해요! | F16: 어머, 한구거를 배워요? 대단해요! | G16: ออมอ ฮันกุกอรึล แบวอโย แดดันแฮโย | H16: โอ๊ะ เรียนภาษาเกาหลีเหรอ เก่งจังเลย!
A17: 16 | B17: สูง | C17: เรื่อง · 오래된 가게 (ร้านเก่าแก่) · ฉาก 6 · คำศัพท์ | E17: 대단해요 | H17: เก่งมาก/สุดยอด
A18: 17 | B18: สูง | C18: เรื่อง · 오래된 가게 (ร้านเก่าแก่) · ฉาก 7 | D18: ผู้เล่น | E18: 아직 잘 못해요. 그래도 매일 할 거예요. | F18: 아직 잘 모태요. 그래도 매일 할 거예요. | G18: อาจิก จัล โมแทโย กือเรโด แมอิล ฮัล กอเยโย | H18: ยังไม่เก่งหรอก แต่จะทำทุกวันค่ะ/ครับ
A19: 18 | B19: สูง | C19: เรื่อง · 오래된 가게 (ร้านเก่าแก่) · ฉาก 7 · คำศัพท์ | E19: 아직 | H19: ยัง
A20: 19 | B20: สูง | C20: เรื่อง · 오래된 가게 (ร้านเก่าแก่) · ฉาก 7 · คำศัพท์ | E20: 그래도 | H20: ถึงอย่างนั้น
A21: 20 | B21: สูง | C21: เรื่อง · 오래된 가게 (ร้านเก่าแก่) · ฉาก 7 · คำศัพท์ | E21: 매일 | H21: ทุกวัน
A22: 21 | B22: สูง | C22: เรื่อง · 오래된 가게 (ร้านเก่าแก่) · ฉาก 8 | D22: ผู้เล่าเรื่อง | E22: 할머니가 가게 안쪽에서 무언가를 가져왔어요. | F22: 할머니가 가게 안쪼게서 무언가를 가져와써요. | G22: ฮัลมอนีกา กาเก อันโจเกซอ มูออนกา กาจยอวัซซอโย | H22: คุณยายเดินเข้าไปด้านในร้าน แล้วหยิบอะไรบางอย่างออกมา
A23: 22 | B23: สูง | C23: เรื่อง · 오래된 가게 (ร้านเก่าแก่) · ฉาก 8 · คำศัพท์ | E23: 안쪽 | H23: ด้านใน
A24: 23 | B24: สูง | C24: เรื่อง · 오래된 가게 (ร้านเก่าแก่) · ฉาก 8 · คำศัพท์ | E24: 가져왔어요 | F24: 가져와써요 | H24: เอามา
A25: 24 | B25: สูง | C25: เรื่อง · 오래된 가게 (ร้านเก่าแก่) · ฉาก 9 | D25: คุณยาย | E25: 사실, 이 알은 오래 기다렸어요. | F25: 사실, 이 아른 오래 기다려써요. | G25: ซาชิล อี อัลรึน โอเร กีดารยอซซอโย | H25: ที่จริงไข่ใบนี้ รอมานานแล้วนะ
A26: 25 | B26: สูง | C26: เรื่อง · 오래된 가게 (ร้านเก่าแก่) · ฉาก 9 · คำศัพท์ | E26: 사실 | H26: ที่จริง
A27: 26 | B27: สูง | C27: เรื่อง · 오래된 가게 (ร้านเก่าแก่) · ฉาก 9 · คำศัพท์ | E27: 알 | H27: ไข่
A28: 27 | B28: สูง | C28: เรื่อง · 오래된 가게 (ร้านเก่าแก่) · ฉาก 9 · คำศัพท์ | E28: 오래 | H28: นาน
A29: 28 | B29: สูง | C29: เรื่อง · 오래된 가게 (ร้านเก่าแก่) · ฉาก 10 | D29: คุณยาย | E29: 한국어를 들려줄 사람을요. | F29: 한구거를 들려줄 사라므료. | G29: ฮันกุกอรึล ดึลลยอจุล ซารามึลโย | H29: รอคนที่จะเล่าภาษาเกาหลีให้มันฟังน่ะ
A30: 29 | B30: สูง | C30: เรื่อง · 오래된 가게 (ร้านเก่าแก่) · ฉาก 10 · คำศัพท์ | E30: 사람 | H30: คน
A31: 30 | B31: สูง | C31: เรื่อง · 오래된 가게 (ร้านเก่าแก่) · ฉาก 10 · คำศัพท์ | E31: 들려주다 | H31: เล่า/ให้ฟัง
A32: 31 | B32: สูง | C32: เรื่อง · 오래된 가게 (ร้านเก่าแก่) · ฉาก 11 | D32: คุณยาย | E32: 이 알을 잘 부탁해요. 공책은 선물이에요. | F32: 이 아를 잘 부타캐요. 공채근 선무리에요. | G32: อี อัลรึล จัล บูทาแคโย กงแชกึน ซอนมูรีเอโย | H32: ฝากไข่ใบนี้ด้วยนะ ส่วนสมุดเล่มนี้ ยายให้เป็นของขวัญ
A33: 32 | B33: สูง | C33: เรื่อง · 오래된 가게 (ร้านเก่าแก่) · ฉาก 11 · คำศัพท์ | E33: 부탁해요 | F33: 부타캐요 | H33: ฝาก/ขอร้อง
A34: 33 | B34: สูง | C34: เรื่อง · 오래된 가게 (ร้านเก่าแก่) · ฉาก 11 · คำศัพท์ | E34: 선물 | H34: ของขวัญ
A35: 34 | B35: สูง | C35: เรื่อง · 오래된 가게 (ร้านเก่าแก่) · ฉาก 12 | D35: ผู้เล่น | E35: 감사합니다! 잘 키울게요. | F35: 감사함니다! 잘 키울게요. | G35: กัมซาฮัมนีดา จัล คิอุลเกโย | H35: ขอบคุณค่ะ/ครับ! จะเลี้ยงให้ดีเลย
A36: 35 | B36: สูง | C36: เรื่อง · 오래된 가게 (ร้านเก่าแก่) · ฉาก 12 · คำศัพท์ | E36: 감사합니다 | F36: 감사함니다 | H36: ขอบคุณ
A37: 36 | B37: สูง | C37: เรื่อง · 오래된 가게 (ร้านเก่าแก่) · ฉาก 12 · คำศัพท์ | E37: 키우다 | H37: เลี้ยง
A38: 37 | B38: สูง | C38: เรื่อง · 오래된 가게 (ร้านเก่าแก่) · ฉาก 13 | D38: คุณยาย | E38: 매일 한국어를 들려주세요. 그럼 알이 깰 거예요. | F38: 매일 한구거를 들려주세요. 그럼 아리 깰 거예요. | G38: แมอิล ฮันกุกอรึล ดึลลยอจูเซโย กือรอม อัลรี เกล กอเยโย | H38: เล่าภาษาเกาหลีให้มันฟังทุกวันนะ แล้วไข่จะฟักเอง
A39: 38 | B39: สูง | C39: เรื่อง · 오래된 가게 (ร้านเก่าแก่) · ฉาก 13 · คำศัพท์ | E39: 들려주세요 | H39: โปรดเล่าให้ฟัง
A40: 39 | B40: สูง | C40: เรื่อง · 오래된 가게 (ร้านเก่าแก่) · ฉาก 14 | D40: ผู้เล่าเรื่อง | E40: 집에 돌아왔어요. | F40: 지베 도라와써요. | G40: จิเบ โดราวัซซอโย | H40: กลับถึงบ้านแล้ว
...

Sheet กิจวัตร
A1: # | B1: ความสำคัญ | C1: ที่มา (หน้า/บท/ฉาก) | D1: ผู้พูด | E1: 한국어 (เกาหลี) | F1: เสียงอ่านจริง (สร้างอัตโนมัติ — กฎการออกเสียง) | G1: คำอ่านไทย (ที่แอปแสดง) | H1: คำแปลไทย (ที่แอปแสดง) | I1: หมายเหตุจากผู้พัฒนา | J1: ① 한국어 ถูกต้อง/เป็นธรรมชาติ? | K1: ① ข้อเสนอแก้ 한국어 | L1: ② คำอ่านไทยตรงกับเสียงจริง? | M1: ② ข้อเสนอคำอ่านไทย | N1: ③ คำแปลไทยถูกต้อง? | O1: ③ ข้อเสนอคำแปล | P1: ความเห็นอื่น ๆ
A2: 1 | B2: กลาง | C2: กิจวัตรประจำวัน | E2: 일어났어요 | F2: 이러나써요 | G2: อีรอนัซซอโย | H2: ตื่นนอนแล้ว
A3: 2 | B3: กลาง | C3: กิจวัตรประจำวัน | E3: 세수했어요 | F3: 세수해써요 | G3: เซซูแฮซซอโย | H3: ล้างหน้าแล้ว
A4: 3 | B4: กลาง | C4: กิจวัตรประจำวัน | E4: 이를 닦았어요 | F4: 이를 다까써요 | G4: อีรึล ดักกัซซอโย | H4: แปรงฟันแล้ว
A5: 4 | B5: กลาง | C5: กิจวัตรประจำวัน | E5: 아침을 먹었어요 | F5: 아치믈 머거써요 | G5: อาชีมึล มอกอซซอโย | H5: กินข้าวเช้าแล้ว
A6: 5 | B6: กลาง | C6: กิจวัตรประจำวัน | E6: 물을 마셨어요 | F6: 무를 마셔써요 | G6: มูรึล มาชยอซซอโย | H6: ดื่มน้ำแล้ว
A7: 6 | B7: กลาง | C7: กิจวัตรประจำวัน | E7: 한국어를 공부했어요 | F7: 한구거를 공부해써요 | G7: ฮันกุกอรึล กงบูแฮซซอโย | H7: เรียนภาษาเกาหลีแล้ว
A8: 7 | B8: กลาง | C8: กิจวัตรประจำวัน | E8: 점심을 먹었어요 | F8: 점시믈 머거써요 | G8: จอมชีมึล มอกอซซอโย | H8: กินข้าวเที่ยงแล้ว
A9: 8 | B9: กลาง | C9: กิจวัตรประจำวัน | E9: 산책했어요 | F9: 산채캐써요 | G9: ซันแชแคซซอโย | H9: ไปเดินเล่นแล้ว
A10: 9 | B10: กลาง | C10: กิจวัตรประจำวัน | E10: 운동했어요 | F10: 운동해써요 | G10: อุนดงแฮซซอโย | H10: ออกกำลังกายแล้ว
A11: 10 | B11: กลาง | C11: กิจวัตรประจำวัน | E11: 저녁을 먹었어요 | F11: 저녀글 머거써요 | G11: จอนยอกึล มอกอซซอโย | H11: กินข้าวเย็นแล้ว
A12: 11 | B12: กลาง | C12: กิจวัตรประจำวัน | E12: 샤워했어요 | F12: 샤워해써요 | G12: ชยาวอแฮซซอโย | H12: อาบน้ำแล้ว
A13: 12 | B13: กลาง | C13: กิจวัตรประจำวัน | E13: 이제 잘 거예요 | G13: อีเจ จัล กอเยโย | H13: กำลังจะนอนแล้ว

Sheet สัตว์เลี้ยง
A1: # | B1: ความสำคัญ | C1: ที่มา (หน้า/บท/ฉาก) | D1: ผู้พูด | E1: 한국어 (เกาหลี) | F1: เสียงอ่านจริง (สร้างอัตโนมัติ — กฎการออกเสียง) | G1: คำอ่านไทย (ที่แอปแสดง) | H1: คำแปลไทย (ที่แอปแสดง) | I1: หมายเหตุจากผู้พัฒนา | J1: ① 한국어 ถูกต้อง/เป็นธรรมชาติ? | K1: ① ข้อเสนอแก้ 한국어 | L1: ② คำอ่านไทยตรงกับเสียงจริง? | M1: ② ข้อเสนอคำอ่านไทย | N1: ③ คำแปลไทยถูกต้อง? | O1: ③ ข้อเสนอคำแปล | P1: ความเห็นอื่น ๆ
A2: 1 | B2: กลาง | C2: คำสั่งสอนสัตว์เลี้ยง | E2: 앉아 | F2: 안자 | G2: อันจา | H2: นั่ง
A3: 2 | B3: กลาง | C3: คำสั่งสอนสัตว์เลี้ยง | E3: 점프 | G3: จอมพือ | H3: กระโดด
A4: 3 | B4: กลาง | C4: คำสั่งสอนสัตว์เลี้ยง | E4: 손 | G4: ซน | H4: ยื่นมือ (จับมือ)
A5: 4 | B5: กลาง | C5: คำสั่งสอนสัตว์เลี้ยง | E5: 엎드려 | F5: 업뜨려 | G5: ออบตือรยอ | H5: หมอบ
A6: 5 | B6: กลาง | C6: คำสั่งสอนสัตว์เลี้ยง | E6: 돌아 | F6: 도라 | G6: โดรา | H6: หมุนตัว
A7: 6 | B7: กลาง | C7: คำสั่งสอนสัตว์เลี้ยง | E7: 굴러 | G7: กุลลอ | H7: กลิ้ง
A8: 7 | B8: กลาง | C8: คำสั่งสอนสัตว์เลี้ยง | E8: 춤춰 | G8: ชุมชวอ | H8: เต้น
A9: 8 | B9: กลาง | C9: คำสั่งสอนสัตว์เลี้ยง | E9: 자 | G9: จา | H9: นอน
A10: 9 | B10: กลาง | C10: คำพูดกับไข่ | E10: 안녕하세요 | G10: อันนยองฮาเซโย | H10: สวัสดี
A11: 10 | B11: กลาง | C11: คำพูดกับไข่ | E11: 좋은 아침이에요 | F11: 조은 아치미에요 | G11: โจอึน อาชีมีเอโย | H11: อรุณสวัสดิ์
A12: 11 | B12: กลาง | C12: คำพูดกับไข่ | E12: 괜찮아요 | F12: 괜차나요 | G12: แควนชานาโย | H12: ไม่เป็นไรนะ
A13: 12 | B13: กลาง | C13: คำพูดกับไข่ | E13: 사랑해 | G13: ซารังแฮ | H13: รักนะ
A14: 13 | B14: กลาง | C14: คำพูดกับไข่ | E14: 잘 자요 | G14: ชัล จาโย | H14: หลับฝันดี
A15: 14 | B15: กลาง | C15: อารมณ์สัตว์เลี้ยง (sleep) | E15: 쿨쿨… 자고 있어요 | F15: 쿨쿨… 자고 이써요 | H15: กำลังหลับปุ๋ย
A16: 15 | B16: กลาง | C16: อารมณ์สัตว์เลี้ยง (hungry) | E16: 배고파요! | F16: 배고파요! | H16: หิวแล้ว ให้อาหารหน่อย
A17: 16 | B17: กลาง | C17: อารมณ์สัตว์เลี้ยง (tired) | E17: 졸려요… | H17: ง่วงแล้ว พาเข้านอนหน่อย
A18: 17 | B18: กลาง | C18: อารมณ์สัตว์เลี้ยง (dirty) | E18: 씻고 싶어요… | F18: 씯꼬 시퍼요… | H18: ตัวเหม็นแล้ว อาบน้ำให้หน่อย
A19: 18 | B19: กลาง | C19: อารมณ์สัตว์เลี้ยง (sad) | E19: 심심해요… | H19: เหงาจัง มาเรียน/เล่นด้วยกันนะ
A20: 19 | B20: กลาง | C20: อารมณ์สัตว์เลี้ยง (happy) | E20: 행복해요! | F20: 행보캐요! | H20: มีความสุขมาก!
A21: 20 | B21: กลาง | C21: อารมณ์สัตว์เลี้ยง (normal) | E21: 안녕! | F21: 안녕! | H21: สบายดี
A22: 21 | B22: กลาง | C22: ชื่อสายพันธุ์ | E22: 호랑이 | G22: โฮรังอี | H22: เสือ
A23: 22 | B23: กลาง | C23: เสียงร้อง | E23: 어흥 | G23: ออฮึง | H23: เสียงคำราม
A24: 23 | B24: กลาง | C24: ชื่อสายพันธุ์ | E24: 병아리 | G24: บยองอารี | H24: ลูกไก่
A25: 24 | B25: กลาง | C25: เสียงร้อง | E25: 삐약 | G25: ปียัก | H25: เสียงลูกไก่ร้อง
A26: 25 | B26: กลาง | C26: ชื่อสายพันธุ์ | E26: 고양이 | G26: โกยังอี | H26: แมว
A27: 26 | B27: กลาง | C27: เสียงร้อง | E27: 야옹 | G27: ยาอง | H27: เสียงแมวร้อง
A28: 27 | B28: กลาง | C28: ชื่อสายพันธุ์ | E28: 강아지 | G28: กังอาจี | H28: ลูกสุนัข
A29: 28 | B29: กลาง | C29: เสียงร้อง | E29: 멍멍 | G29: มองมอง | H29: เสียงสุนัขเห่า
A30: 29 | B30: กลาง | C30: ชื่อสายพันธุ์ | E30: 토끼 | G30: โทกี | H30: กระต่าย
A31: 30 | B31: กลาง | C31: เสียงร้อง | E31: 깡충 | G31: กังชุง | H31: เสียงกระโดดของกระต่าย
A32: 31 | B32: กลาง | C32: ชื่อสายพันธุ์ | E32: 여우 | G32: ยอู | H32: จิ้งจอก
A33: 32 | B33: กลาง | C33: เสียงร้อง | E33: 컹컹 | G33: คองคง | H33: เสียงจิ้งจอกร้อง
... A35: 34 | B35: กลาง | C35: เสียงร้อง | E35: 냠냠 | G35: นยัมนยัม | H35: เสียงกินอาหาร

Sheet ภารกิจ-ความสำเร็จ
A1: # | B1: ความสำคัญ | C1: ที่มา (หน้า/บท/ฉาก) | D1: ผู้พูด | E1: 한국어 (เกาหลี) | F1: เสียงอ่านจริง (สร้างอัตโนมัติ — กฎการออกเสียง) | G1: คำอ่านไทย (ที่แอปแสดง) | H1: คำแปลไทย (ที่แอปแสดง) | I1: หมายเหตุจากผู้พัฒนา | J1: ① 한국어 ถูกต้อง/เป็นธรรมชาติ? | K1: ① ข้อเสนอแก้ 한국어 | L1: ② คำอ่านไทยตรงกับเสียงจริง? | M1: ② ข้อเสนอคำอ่านไทย | N1: ③ คำแปลไทยถูกต้อง? | O1: ③ ข้อเสนอคำแปล | P1: ความเห็นอื่น ๆ
A2: 1 | B2: กลาง | C2: ภารกิจรายวัน | E2: 수업 1개 끝내기 | F2: 수업 1개 끈내기 | H2: เรียนจบ 1 บทวันนี้
A3: 2 | B3: กลาง | C3: ภารกิจรายวัน | E3: 복습 5개 맞히기 | F3: 복씁 5개 마티기 | H3: ทบทวนตอบถูก 5 คำ
A4: 3 | B4: กลาง | C4: ภารกิจรายวัน | E4: 글자 3개 만들기 | H4: ประกอบพยางค์ให้ถูก 3 คำ
A5: 4 | B5: กลาง | C5: ภารกิจรายวัน | E5: 루틴 3개 하기 | H5: ติ๊กกิจวัตรจริง 3 ข้อ
A6: 5 | B6: กลาง | C6: ภารกิจรายวัน | E6: 만점 받기 | F6: 만점 받끼 | H6: ทำแบบทดสอบบทเรียนได้คะแนนเต็ม 1 ครั้ง
A7: 6 | B7: กลาง | C7: ภารกิจรายวัน | E7: 말하기 3번 | H7: พูดตามให้ผ่าน 3 ประโยค
A8: 7 | B8: กลาง | C8: ภารกิจรายวัน | E8: 펫 돌보기 3번 | F8: 펟 돌보기 3번 | H8: ดูแลสัตว์เลี้ยง 3 ครั้ง (ให้อาหาร/เล่น/อาบน้ำ)
A9: 8 | B9: กลาง | C9: ความสำเร็จ | E9: 첫 수업 | F9: 첟 수업 | H9: เรียนจบบทแรก
A10: 9 | B10: กลาง | C10: ความสำเร็จ | E10: 한글 졸업 | F10: 한글 조럽 | H10: จบบทฮันกึลครบทั้ง 3 บท
A11: 10 | B11: กลาง | C11: ความสำเร็จ | E11: 만점! | F11: 만점! | H11: ได้คะแนนเต็มในบทเรียน
A12: 11 | B12: กลาง | C12: ความสำเร็จ | E12: 단어 30개 | F12: 다너 30개 | H12: เก็บคำศัพท์ได้ 30 คำ
A13: 12 | B13: กลาง | C13: ความสำเร็จ | E13: 단어 100개 | F13: 다너 100개 | H13: เก็บคำศัพท์ได้ 100 คำ
A14: 13 | B14: กลาง | C14: ความสำเร็จ | E14: 첫 발음 | F14: 첟 바름 | H14: พูดตามผ่านครั้งแรก
A15: 14 | B15: กลาง | C15: ความสำเร็จ | E15: 말하기 달인 | F15: 말하기 다린 | H15: พูดตามผ่านครบ 50 ประโยค
A16: 15 | B16: กลาง | C16: ความสำเร็จ | E16: 동물 친구들 | H16: มีสัตว์เลี้ยงครบ 3 สายพันธุ์
A17: 16 | B17: กลาง | C17: ความสำเร็จ | E17: 동물원 | F17: 동무뤈 | H17: สะสมสัตว์เลี้ยงครบทุกสายพันธุ์
A18: 17 | B18: กลาง | C18: ความสำเร็จ | E18: 단짝 | H18: ความผูกพันกับสัตว์เลี้ยงถึงระดับ 3
A19: 18 | B19: กลาง | C19: ความสำเร็จ | E19: 훈련사 | F19: 훌련사 | H19: สอนคำสั่งครบทุกท่าในวันเดียว
A20: 19 | B20: กลาง | C20: ความสำเร็จ | E20: 3일 연속 | H20: เล่นต่อเนื่อง 3 วัน
A21: 20 | B21: กลาง | C21: ความสำเร็จ | E21: 7일 연속 | H21: เล่นต่อเนื่อง 7 วัน
A22: 21 | B22: กลาง | C22: ความสำเร็จ | E22: 30일 연속 | H22: เล่นต่อเนื่อง 30 วัน
A23: 22 | B23: กลาง | C23: ความสำเร็จ | E23: 알이 깼어요 | F23: 아리 깨써요 | H23: ฟักไข่สัตว์เลี้ยงสำเร็จ
A24: 23 | B24: กลาง | C24: ความสำเร็จ | E24: 멋진 친구 | F24: 먿찐 친구 | H24: เลี้ยงสัตว์เลี้ยงจนโตเต็มวัย
A25: 24 | B25: กลาง | C25: ความสำเร็จ | E25: Lv.5 | H25: ถึงเลเวล 5
A26: 25 | B26: กลาง | C26: ความสำเร็จ | E26: Lv.10 | H26: ถึงเลเวล 10
A27: 26 | B27: กลาง | C27: ความสำเร็จ | E27: 쇼핑왕 | H27: มีไอเทมครบ 15 ชิ้น
A28: 27 | B28: กลาง | C28: ความสำเร็จ | E28: 수집가 | F28: 수집까 | H28: สะสมไอเทมครบ 30 ชิ้น
A29: 28 | B29: กลาง | C29: ความสำเร็จ | E29: 대수집가 | F29: 대수집까 | H29: สะสมไอเทมครบ 60 ชิ้น
A30: 29 | B30: กลาง | C30: ความสำเร็จ | E30: 전설 획득 | F30: 전설 획뜩 | H30: ได้ไอเทมระดับตำนานชิ้นแรก
A31: 30 | B31: กลาง | C31: ความสำเร็จ | E31: 루틴 완료 | F31: 루틴 왈료 | H31: ติ๊กกิจวัตรครบทุกข้อในวันเดียว
A32: 31 | B32: กลาง | C32: ความสำเร็จ | E32: 퀘스트 완료 | F32: 퀘스트 왈료 | H32: รับภารกิจประจำวันครบทุกข้อ
A33: 32 | B33: กลาง | C33: ความสำเร็จ | E33: 글자 장인 | H33: ประกอบพยางค์ผ่านครบโควตาวันหนึ่ง
A34: 33 | B34: กลาง | C34: ความสำเร็จ | E34: 학교 세트 | F34: 학꾜 세트 | H34: สะสมครบชุด ชุดนักเรียน (6 ชิ้น)
A35: 34 | B35: กลาง | C35: ความสำเร็จ | E35: 한복 세트 | H35: สะสมครบชุด ชุดฮันบก (6 ชิ้น)
A36: 35 | B36: กลาง | C36: ความสำเร็จ | E36: 겨울 세트 | H36: สะสมครบชุด หน้าหนาว (8 ชิ้น)
A37: 36 | B37: กลาง | C37: ความสำเร็จ | E37: 아이돌 세트 | H37: สะสมครบชุด ไอดอล (8 ชิ้น)
A38: 37 | B38: กลาง | C38: ความสำเร็จ | E38: 카페 세트 | H38: สะสมครบชุด คาเฟ่ (8 ชิ้น)
A39: 38 | B39: กลาง | C39: ความสำเร็จ | E39: 스포츠 세트 | H39: สะสมครบชุด สายกีฬา (6 ชิ้น)
A40: 39 | B40: กลาง | C40: ความสำเร็จ | E40: 스트릿 세트 | F40: 스트릳 세트 | H40: สะสมครบชุด สตรีท (7 ชิ้น)
...

Sheet ร้านค้า
A1: # | B1: ความสำคัญ | C1: ที่มา (หน้า/บท/ฉาก) | D1: ผู้พูด | E1: 한국어 (เกาหลี) | F1: เสียงอ่านจริง (สร้างอัตโนมัติ — กฎการออกเสียง) | G1: คำอ่านไทย (ที่แอปแสดง) | H1: คำแปลไทย (ที่แอปแสดง) | I1: หมายเหตุจากผู้พัฒนา | J1: ① 한국어 ถูกต้อง/เป็นธรรมชาติ? | K1: ① ข้อเสนอแก้ 한국어 | L1: ② คำอ่านไทยตรงกับเสียงจริง? | M1: ② ข้อเสนอคำอ่านไทย | N1: ③ คำแปลไทยถูกต้อง? | O1: ③ ข้อเสนอคำแปล | P1: ความเห็นอื่น ๆ
A2: 1 | B2: ต่ำ | C2: อาหารสัตว์เลี้ยง | E2: 우유 | G2: อูยู | H2: นม
A3: 2 | B3: ต่ำ | C3: อาหารสัตว์เลี้ยง | E3: 바나나우유 | G3: บานานาอูยู | H3: นมกล้วย
A4: 3 | B4: ต่ำ | C4: อาหารสัตว์เลี้ยง | E4: 김밥 | G4: กิมบับ | H4: กิมบับ
A5: 4 | B5: ต่ำ | C5: อาหารสัตว์เลี้ยง | E5: 떡볶이 | F5: 떡뽀끼 | G5: ต็อกโปกี | H5: ต็อกโปกี
A6: 5 | B6: ต่ำ | C6: อาหารสัตว์เลี้ยง | E6: 송편 | G6: ซงพยอน | H6: ซงพยอน (ขนมข้าวชูซอก)
A7: 6 | B7: ต่ำ | C7: อาหารสัตว์เลี้ยง | E7: 삼겹살 | F7: 삼겹쌀 | G7: ซัมกยอบซัล | H7: หมูสามชั้นย่าง
A8: 7 | B8: ต่ำ | C8: ไอเทมแต่งตัว (top) | E8: 파란 티셔츠 | H8: เสื้อยืดสีฟ้า
A9: 8 | B9: ต่ำ | C9: ไอเทมแต่งตัว (top) | E9: 빨간 후드티 | H9: ฮู้ดสีแดง
A10: 9 | B10: ต่ำ | C10: ไอเทมแต่งตัว (top) | E10: 초록 티셔츠 | H10: เสื้อยืดสีเขียว
A11: 10 | B11: ต่ำ | C11: ไอเทมแต่งตัว (top) | E11: 노란 티셔츠 | H11: เสื้อยืดสีเหลือง
A12: 11 | B12: ต่ำ | C12: ไอเทมแต่งตัว (top) | E12: 분홍 티셔츠 | H12: เสื้อยืดสีชมพู
A13: 12 | B13: ต่ำ | C13: ไอเทมแต่งตัว (top) | E13: 검은 티셔츠 | F13: 거믄 티셔츠 | H13: เสื้อยืดสีดำ
A14: 13 | B14: ต่ำ | C14: ไอเทมแต่งตัว (top) | E14: 교복 | H14: ชุดนักเรียน
A15: 14 | B15: ต่ำ | C15: ไอเทมแต่งตัว (top) | E15: 한복 | H15: ชุดฮันบก
A16: 15 | B16: ต่ำ | C16: ไอเทมแต่งตัว (bottom) | E16: 남색 바지 | H16: กางเกงสีกรม
A17: 16 | B17: ต่ำ | C17: ไอเทมแต่งตัว (bottom) | E17: 남색 치마 | H17: กระโปรงสีกรม
A18: 17 | B18: ต่ำ | C18: ไอเทมแต่งตัว (bottom) | E18: 카키 바지 | H18: กางเกงสีกากี
A19: 18 | B19: ต่ำ | C19: ไอเทมแต่งตัว (bottom) | E19: 청반바지 | H19: กางเกงยีนส์ขาสั้น
A20: 19 | B20: ต่ำ | C20: ไอเทมแต่งตัว (bottom) | E20: 분홍 치마 | H20: กระโปรงสีชมพู
A21: 20 | B21: ต่ำ | C21: ไอเทมแต่งตัว (bottom) | E21: 검은 바지 | F21: 거믄 바지 | H21: กางเกงสีดำ
A22: 21 | B22: ต่ำ | C22: ไอเทมแต่งตัว (shoes) | E22: 운동화 | H22: รองเท้าผ้าใบสีขาว
A23: 22 | B23: ต่ำ | C23: ไอเทมแต่งตัว (shoes) | E23: 부츠 | H23: รองเท้าบูท
A24: 23 | B24: ต่ำ | C24: ไอเทมแต่งตัว (hat) | E24: 비니 | H24: หมวกไหมพรม
A25: 24 | B25: ต่ำ | C25: ไอเทมแต่งตัว (hat) | E25: 머리띠 | H25: ที่คาดผม
A26: 25 | B26: ต่ำ | C26: ไอเทมแต่งตัว (hat) | E26: 꽃 핀 | F26: 꼳 핀 | H26: กิ๊บดอกไม้
A27: 26 | B27: ต่ำ | C27: ไอเทมแต่งตัว (hat) | E27: 야구 모자 | H27: หมวกแก๊ป
A28: 27 | B28: ต่ำ | C28: ไอเทมแต่งตัว (hat) | E28: 고양이 귀 | H28: ที่คาดผมหูแมว
A29: 28 | B29: ต่ำ | C29: ไอเทมแต่งตัว (hat) | E29: 베레모 | H29: หมวกเบเร่ต์
A30: 29 | B30: ต่ำ | C30: ไอเทมแต่งตัว (hat) | E30: 토끼 귀 | H30: ที่คาดผมหูกระต่าย
A31: 30 | B31: ต่ำ | C31: ไอเทมแต่งตัว (hat) | E31: 갓 | F31: 갇 | H31: หมวกกัด (โบราณ)
A32: 31 | B32: ต่ำ | C32: ไอเทมแต่งตัว (hat) | E32: 왕관 | H32: มงกุฎ
A33: 32 | B33: ต่ำ | C33: ไอเทมแต่งตัว (hat) | E33: 호랑이 귀 | H33: หูเสือ (ของพิเศษ)
A34: 33 | B34: ต่ำ | C34: ไอเทมแต่งตัว (glasses) | E34: 안경 | H34: แว่นตา
A35: 34 | B35: ต่ำ | C35: ไอเทมแต่งตัว (glasses) | E35: 동그란 안경 | H35: แว่นกลม
A36: 35 | B36: ต่ำ | C36: ไอเทมแต่งตัว (glasses) | E36: 선글라스 | H36: แว่นกันแดด
A37: 36 | B37: ต่ำ | C37: ไอเทมแต่งตัว (neck) | E37: 나비넥타이 | H37: โบว์ผูกคอ
A38: 37 | B38: ต่ำ | C38: ไอเทมแต่งตัว (neck) | E38: 목도리 | F38: 목또리 | H38: ผ้าพันคอ
A39: 38 | B39: ต่ำ | C39: ไอเทมแต่งตัว (neck) | E39: 목걸이 | F39: 목꺼리 | H39: สร้อยคอ
A40: 39 | B40: ต่ำ | C40: ไอเทมแต่งตัว (neck) | E40: 메달 | H40: เหรียญรางวัล (ของพิเศษ)
...

Sheet ฟังเสียง
A1: เสียงพูดที่อยากให้ฟัง (เปิดแอป → ปุ่ม 🔊 ของคำนั้น) | B1: ข้อความ | C1: วิธีไปฟัง | D1: เหตุผลที่ขอให้ฟัง | E1: ฟังแล้วเป็นอย่างไร? | F1: ความเห็น
A2: ครูฮานา และครูมินจุน (เลือกใน ⚙ ตั้งค่า) | B2: 오래 | C2: เรื่องตอน 1 · ช่วง 알 (คุณยายพูดว่า "이 알은 오래 기다렸어요") → หน้าสรุปคำศัพท์ ปุ่ม 🔊 | D2: เครื่องตรวจอัตโนมัติจับคำได้ต่ำ (ครูมินจุน 0%, ครูฮานา 50%) อาจเพี้ยนจริงหรืออาจเป็นข้อจำกัดของเครื่องตรวจ
A3: ครูฮานา และครูมินจุน (เลือกใน ⚙ ตั้งค่า) | B3: 곶감 | C3: เรื่องตอน 1 · ช่วง "นิทานเสือกับลูกพลับแห้ง" (c1_tale) และคำตอบในตอน 3 | D3: คำที่เจอยากสำหรับเครื่อง (ทั้งสองเสียง 50%)
A4: ครูฮานา และครูมินจุน (เลือกใน ⚙ ตั้งค่า) | B4: 익어요 | C4: เรื่องตอน 3 · ช่วงทำซงพยอน ("솥에서 송편이 익어 가요") | D4: ทั้งสองเสียง 33%
A5: ครูฮานา และครูมินจุน (เลือกใน ⚙ ตั้งค่า) | B5: 어떻게 | C5: เรื่องตอน 3 · ช่วงทำซงพยอน ("어떻게 접었어요?") | D5: ครูฮานา 33%
A6: ครูฮานา และครูมินจุน (เลือกใน ⚙ ตั้งค่า) | B6: 돼요 | C6: เรื่องตอน 1 ("닭이 돼요") และตอน 3 ("이렇게 하면 돼요?") · บทเรียนร้านค้า ("카드 돼요?") | D6: ครูฮานา 50%
A7: ครูฮานา และครูมินจุน (เลือกใน ⚙ ตั้งค่า) | B7: 옛날 옛적에 | C7: เรื่องตอน 1 · นิทานเสือ ("옛날 옛적에 호랑이가 있었어요") | D7: ครูมินจุน 80%
A8: ครูฮานา และครูมินจุน (เลือกใน ⚙ ตั้งค่า) | B8: 기다려져요 | C8: เรื่องตอน 2 (จบ) และตอน 3 ("설날이 기다려져요") | D8: ทั้งสองเสียง 80%
A9: ครูฮานา และครูมินจุน (เลือกใน ⚙ ตั้งค่า) | B9: 죄송합니다 | C9: บทเรียน 인사 → ปุ่ม 🐢 ช้า | D9: คลิป "ช้า" ถูกยืดเวลา ×1.5 ตรวจ 40% (ครูมินจุน) — ฟังว่ายังเป็นธรรมชาติไหม
A10: ครูฮานา และครูมินจุน (เลือกใน ⚙ ตั้งค่า) | B10: 요리하다 | C10: บทเรียน → ปุ่ม 🐢 ช้า | D10: คลิป "ช้า" ตรวจ 50–75%
A11: ครูฮานา และครูมินจุน (เลือกใน ⚙ ตั้งค่า) | B11: 이를 닦다 | C11: บทเรียน → ปุ่ม 🐢 ช้า | D11: คลิป "ช้า" ตรวจ 75%
A12: ครูฮานา และครูมินจุน (เลือกใน ⚙ ตั้งค่า) | B12: ㄱ ㄴ ㄷ … (ชื่อพยัญชนะ 기역 니은 디귿) | C12: บทเรียน 자음 → ปุ่ม 🔊 / 🐢 | D12: พยางค์เดี่ยว/ชื่อตัวอักษรตรวจอัตโนมัติไม่ได้ ต้องฟังด้วยหูเท่านั้น
A13: ครูฮานา และครูมินจุน (เลือกใน ⚙ ตั้งค่า) | B13: 케이크 / 손풍선 / 곰이요 | C13: เรื่อง/สัตว์เลี้ยง | D13: คำที่ผู้พัฒนายังไม่เคยฟังยืนยัน
